Workbook

Sheet Instrucciones
A1: INSTRUCCIONES · EXPORTAR DE FORMSPREE → ENVIAR EMAIL
A3: PASO | B3: ACCIÓN
A4: 1 | B4: Andá a https://formspree.io/forms y hacé login
A5: 2 | B5: Click en tu form del taller
A6: 3 | B6: Click en la pestaña 'Submissions' (Submisiones)
A7: 4 | B7: Botón superior derecho: 'Export' → elegí 'CSV'
A8: 5 | B8: Abrí el CSV en Excel (doble click)
A9: 6 | B9: Copiá las columnas: nombre, email, país, nivel, razón
A10: 7 | B10: Pegalas en la hoja 'Inscritos Taller 6Jun' empezando en B5
A11: 8 | B11: Revisá la pestaña 'Dashboard' para ver el total de inscritos
A12: 9 | B12: Andá a 'BCC List (Gmail)' y copiá la celda A4 completa
A13: 10 | B13: Abrí Gmail → Redactar nuevo email
A14: 11 | B14: En 'Para:' poné jay@academiaseul.com (TU email)
... A21: 18 | B21: Después de 24h, revisá el dashboard para ver respuestas

Sheet Inscritos Taller 6Jun
A1: ACADEMIA SEUL · INSCRITOS TALLER 6 JUNIO 2026
A2: Pega aquí los inscritos exportados de Formspree. Usa la columna 'Estado Email' para trackear.
A4: # | B4: Nombre | C4: Email | D4: País | E4: Nivel Coreano | F4: Razón / Comentario | G4: Fecha Inscripción | H4: Estado Email | I4: Notas
A5: =ROW()-4 -> 1 | B5: María Elisa Alvarez | C5: mariaelisa1967@gmail.com | D5: Venezuela | E5: Hangul básico | F5: Viaje a Corea ️ | Edad 55+ | G5: 2026-05-30 | H5: Pendiente
A6: =ROW()-4 -> 2 | B6: Paula Castellón | C6: paulinas.boutique75@gmail.com | D6: Nicaragua | F6: Cultura coreana en general | Edad 45 - 54 | G6: 2026-05-29 | H6: Pendiente
A7: =ROW()-4 -> 3 | B7: Constanza | C7: constanzapaulette.castro@gmail.com | D7: Chile | E7: K-pop/K-drama | F7: K-pop | Edad 35 - 44 | G7: 2026-05-29 | H7: Pendiente
A8: =ROW()-4 -> 4 | B8: Jessica | C8: jessica.alcayagao@gmail.com | D8: Chile | E8: Cero | F8: Por curiosidad / hobby | Edad 55+ | G8: 2026-05-29 | H8: Pendiente
A9: =ROW()-4 -> 5 | B9: Gabriela | C9: gpb7124@live.com.mx | D9: México | E9: Hangul básico | F9: K-pop | Edad 55+ | G9: 2026-05-29 | H9: Pendiente
A10: =ROW()-4 -> 6 | B10: Veronica | C10: veronik3340@gmail.com | D10: Argentina | E10: K-pop/K-drama | F10: Viaje a Corea ️ | Edad 45 - 54 | G10: 2026-05-29 | H10: Pendiente
A11: =ROW()-4 -> 7 | B11: Sonia | C11: sonychas72@gmail.com | E11: K-pop/K-drama | F11: Viaje a Corea ️ | Edad 45 - 54 | G11: 2026-05-29 | H11: Pendiente
A12: =ROW()-4 -> 8 | B12: Delia | C12: elisard2514@gmail.com | D12: México | E12: Cero | F12: Trabajo o negocios | Edad 55+ | G12: 2026-05-29 | H12: Pendiente
A13: =ROW()-4 -> 9 | B13: Gabriela | C13: gabrielafiumarelli@gmail.com | D13: Argentina | E13: Hangul básico | F13: Trabajo o negocios | Edad 45 - 54 | G13: 2026-05-29 | H13: Pendiente
A14: =ROW()-4 -> 10 | B14: Alejandro | C14: 444fegugoga@gmail.com | D14: Chile | E14: Cero | F14: Cultura coreana en general | Edad 35 - 44 | G14: 2026-05-29 | H14: Pendiente
A15: =ROW()-4 -> 11 | B15: victoria | C15: lyorgelis726@gmail.com | D15: Chile | E15: K-pop/K-drama | F15: Cultura coreana en general | Edad 18 - 24 | G15: 2026-05-28 | H15: Pendiente
A16: =ROW()-4 -> 12 | B16: Makoke Sánchez | C16: sanchezmakoke@gmail.com | D16: 🌍 Otro | E16: Hangul básico | F16: Por curiosidad / hobby | Edad 55+ | G16: 2026-05-26 | H16: Pendiente
A17: =ROW()-4 -> 13 | B17: Ariana | C17: ariana01013@gmail.com | D17: Perú | E17: Cero | F17: Por curiosidad / hobby | Edad Menor de 18 | G17: 2026-05-25 | H17: Pendiente
A18: =ROW()-4 -> 14 | B18: Flor | C18: florenciaoliva80@gmail.com | D18: Argentina | E18: Cero | F18: Trabajo o negocios | Edad 45 - 54 | G18: 2026-05-25 | H18: Pendiente
A19: =ROW()-4 -> 15 | B19: Cecilia | C19: jesma21@gmail.com | D19: Chile | E19: Cero | F19: K-dramas / Netflix | Edad 35 - 44 | G19: 2026-05-25 | H19: Pendiente
A20: =ROW()-4 -> 16 | B20: Rommy arreola | C20: rommy.an1@gmail.com | D20: México | E20: Hangul básico | F20: Por curiosidad / hobby | Edad 55+ | G20: 2026-05-24 | H20: Pendiente
A21: =ROW()-4 -> 17 | B21: César Jácome Gutiérrez | C21: cesarin.bebe5@gmail.com | E21: Cero | F21: K-dramas / Netflix | Edad 55+ | G21: 2026-05-24 | H21: Pendiente
A22: =ROW()-4 -> 18 | B22: Marlyn Velazquez | C22: rosmarly.17679864@gmail.com | D22: Venezuela | E22: K-pop/K-drama | F22: Viaje a Corea ️ | Edad 35 - 44 | G22: 2026-05-23 | H22: Pendiente
A23: =ROW()-4 -> 19 | B23: Lidia | C23: pinoleolidia61@gmail.com | D23: Chile | E23: Cero | F23: Cultura coreana en general | G23: 2026-05-22 | H23: Pendiente
A24: =ROW()-4 -> 20 | B24: Yarice quintero | C24: yaricequintero@gmail.com | D24: Chile | E24: K-pop/K-drama | F24: Cultura coreana en general | Edad 35 - 44 | G24: 2026-05-22 | H24: Pendiente
A25: =ROW()-4 -> 21 | B25: Adriana Rodriguez | C25: adrianacrys@gmail.com | E25: Hangul básico | F25: K-dramas / Netflix | Edad 45 - 54 | G25: 2026-05-22 | H25: Pendiente
A26: =ROW()-4 -> 22 | B26: Mazziel castellano | C26: mazzielcastellano91@gmail.com | D26: Venezuela | E26: K-pop/K-drama | F26: Por curiosidad / hobby | Edad 25 - 34 | G26: 2026-05-22 | H26: Pendiente
A27: =ROW()-4 -> 23 | B27: Dora Loaiza | C27: dorital12@hotmail.com | D27: Ecuador | E27: Hangul básico | F27: Cultura coreana en general | Edad 55+ | G27: 2026-05-22 | H27: Pendiente
A28: =ROW()-4 -> 24 | B28: Consuelo Aguilar | C28: consueloaguilar321@gmail.com | D28: Honduras | E28: Cero | F28: Cultura coreana en general | Edad 55+ | G28: 2026-05-21 | H28: Pendiente
A29: =ROW()-4 -> 25 | B29: Andrea | C29: andrea.rojas.abarzua@hotmail.com | D29: Chile | E29: Cero | F29: Viaje a Corea ️ | Edad 45 - 54 | G29: 2026-05-21 | H29: Pendiente
A30: =ROW()-4 -> 26 | B30: Alejandra Araya | C30: amarayar@gmail.com | D30: Chile | E30: K-pop/K-drama | F30: Cultura coreana en general | Edad 35 - 44 | G30: 2026-05-21 | H30: Pendiente
A31: =ROW()-4 -> 27 | B31: Lucia | C31: lucia.hangug@gmail.com | D31: México | E31: A1-A2 | F31: K-dramas / Netflix | Edad 45 - 54 | G31: 2026-05-21 | H31: Pendiente
A32: =ROW()-4 -> 28 | B32: Sara Rodriguez | C32: sandrea.rodriguezc.sr@gmail.com | D32: Chile | E32: Hangul básico | F32: Trabajo o negocios | Edad 45 - 54 | G32: 2026-05-20 | H32: Pendiente
A33: =ROW()-4 -> 29 | B33: Rosibel | C33: rosiperez2007@gmail.com | D33: Venezuela | E33: K-pop/K-drama | F33: Cultura coreana en general | Edad 45 - 54 | G33: 2026-05-20 | H33: Pendiente
A34: =ROW()-4 -> 30 | B34: Ingrid Rodriguez | C34: ingrid.rodriguez.labra@gmail.com | D34: Chile | E34: K-pop/K-drama | F34: Cultura coreana en general | Edad 35 - 44 | G34: 2026-05-20 | H34: Pendiente
A35: =ROW()-4 -> 31 | B35: Norma | C35: nomyguilleng@hotmail.com | D35: Perú | E35: Cero | F35: Viaje a Corea ️ | Edad 45 - 54 | G35: 2026-05-20 | H35: Pendiente
A36: =ROW()-4 -> 32 | B36: Yenny Colina Reyes | C36: yennycolina67@gmail.com | D36: Venezuela | E36: K-pop/K-drama | F36: Cultura coreana en general | Edad 35 - 44 | G36: 2026-05-20 | H36: Pendiente
A37: =ROW()-4 -> 33 | B37: Jessica carmona | C37: yexikarmona@hotmail.com | D37: Chile | E37: K-pop/K-drama | F37: Cultura coreana en general | Edad 35 - 44 | G37: 2026-05-18 | H37: Pendiente
... A39: =ROW()-4 -> 35 | B39: Luz | C39: luzlinarojasch@gmail.com | D39: Perú | E39: K-pop/K-drama | F39: Cultura coreana en general | G39: 2026-05-18 | H39: Pendiente
A40: =ROW()-4 -> 36 | B40: Rodrigo Gálvez | C40: rodrigo.galvez@seasmin.com | E40: Cero | F40: Coreano General | 💬 Me gustaría aprender coreano de forma online ,ya que vivo en region | 📞 935263101 | G40: 2026-05-16 | H40: Pendiente
A41: =ROW()-4 -> 37 | B41: Alejandra | C41: alee7slzr@gmail.com | D41: Venezuela | E41: K-pop/K-drama | F41: Viaje a Corea ️ | Edad 25 - 34 | G41: 2026-05-12 | H41: Pendiente
A42: =ROW()-4 -> 38 | B42: Gabriela Fonseca | C42: gabrielafmonasterio@gmail.com | D42: Venezuela | E42: Cero | F42: K-pop | Edad 35 - 44 | G42: 2026-05-11 | H42: Pendiente
...

Sheet Dashboard
A1: DASHBOARD · INSCRITOS TALLER 6 JUNIO
A3: Métrica | B3: Valor
A4: Total Inscritos | B4: =COUNTA('Inscritos Taller 6Jun'!C5:C104) -> 50
A5: Emails Enviados | B5: =COUNTIF('Inscritos Taller 6Jun'!H5:H104,"Enviado") -> 0
A6: Emails Pendientes | B6: =COUNTIF('Inscritos Taller 6Jun'!H5:H104,"Pendiente") -> 50
A7: Rebotaron | B7: =COUNTIF('Inscritos Taller 6Jun'!H5:H104,"Rebotó") -> 0
A8: Respondieron | B8: =COUNTIF('Inscritos Taller 6Jun'!H5:H104,"Respondió") -> 0
A9: Inscribieron a Nivel 1 ($89) | B9: =COUNTIF('Inscritos Taller 6Jun'!H5:H104,"Inscribió Nivel 1") -> 0
A10: Tasa Conversión a Nivel 1 | B10: =IFERROR(B7/B2,0) -> 0
A11: Revenue Estimado USD | B11: =B7*89 -> 0
A13: Top Países
A14: País | B14: Cantidad
A15: Chile | B15: =COUNTIF('Inscritos Taller 6Jun'!D5:D104,"Chile") -> 12
A16: México | B16: =COUNTIF('Inscritos Taller 6Jun'!D5:D104,"México") -> 4
A17: Colombia | B17: =COUNTIF('Inscritos Taller 6Jun'!D5:D104,"Colombia") -> 0
A18: Perú | B18: =COUNTIF('Inscritos Taller 6Jun'!D5:D104,"Perú") -> 3
A19: Argentina | B19: =COUNTIF('Inscritos Taller 6Jun'!D5:D104,"Argentina") -> 5
A20: España | B20: =COUNTIF('Inscritos Taller 6Jun'!D5:D104,"España") -> 0
A21: Venezuela | B21: =COUNTIF('Inscritos Taller 6Jun'!D5:D104,"Venezuela") -> 17
A22: Ecuador | B22: =COUNTIF('Inscritos Taller 6Jun'!D5:D104,"Ecuador") -> 1

Sheet BCC List (Gmail)
A1: LISTA BCC · PARA PEGAR EN GMAIL
A2: Copia la celda A4 (todos los emails separados por coma) y pégala en el campo BCC/CCO de Gmail
A3: Emails (BCC ready)
A4: =_xlfn.TEXTJOIN(", ",TRUE(),'Inscritos Taller 6Jun'!C5:C104) -> mariaelisa1967@gmail.com, paulinas.boutique75@gmail.com, constanzapaulette.castro@gmail.com, jessica.alcayagao@gmail.com, gpb7124@live.com.mx, veronik3340@gmail.com, sonychas72@gmail.com, elisard2514@gmail.com, gabrielafiumarelli@gmail.com, 444fegugoga@gmail.com, lyorgelis726@gmail.com, sanchezmakoke@gmail.com, ariana01013@gmail.com, florenciaoliva80@gmail.com, jesma21@gmail.com, rommy.an1@gmail.com, cesarin.bebe5@gmail.com, rosmarly.17679864@gmail.com, pinoleolidia61@gmail.com, yaricequintero@gmail.com, adrianacrys@gmail.com, mazzielcastellano91@gmail.com, dorital12@hotmail.com, consueloaguilar321@gmail.com, andrea.rojas.abarzua@hotmail.com, amarayar@gmail.com, lucia.hangug@gmail.com, sandrea.rodriguezc.sr@gmail.com, rosiperez2007@gmail.com, ingrid.rodriguez.labra@gmail.com, nomyguilleng@hotmail.com, yennycolina67@gmail.com, yexikarmona@hotmail.com, elsitajesus2000@gmail.com, luzlinarojasch@gmail.com, rodrigo.galvez@seasmin.com, alee7slzr@gmail.com, gabrielafmonasterio@gmail.com, yethsyruiz@gmail.com, mariananatalirodriguezmendez@gmail.com, diazmilagros@yahoo.es, daisyalanna.20@gmail.com, merycataleya438@gmail.com, fabriellysh89@gmail.com, hillaryparissojolanda@gmail.com, danieka35@gmail.com, perezruizrosibel@gmail.com, raizaramirez1234@gmail.com, lajsysyelis@gmail.com, sukdaiana@hotmail.com
A6: ⚠️ IMPORTANTE: Gmail limita a 500 destinatarios por email. Si tenés más de 500 inscritos, divídelos en 2 envíos.
A7: 💡 TIP: Una vez pegados los emails en BCC, asegúrate que el campo 'Para:' tenga TU PROPIO email.
